<?xml version="1.0"?>
<robot name="mini_arm">

  <!-- Base Link -->
  <link name="base_link">
    <visual>
      <geometry>
        <box size="0.2 0.2 0.05"/>
      </geometry>
      <material name="gray">
        <color rgba="0.6 0.6 0.6 1"/>
      </material>
    </visual>
  </link>

  <!-- First Arm Link -->
  <link name="link1">
    <visual>
      <geometry>
        <cylinder length="0.4" radius="0.03"/>
      </geometry>
      <material name="blue">
        <color rgba="0 0 1 1"/>
      </material>
    </visual>
  </link>

  <!-- Second Arm Link -->
  <link name="link2">
    <visual>
      <geometry>
        <cylinder length="0.3" radius="0.025"/>
      </geometry>
      <material name="green">
        <color rgba="0 1 0 1"/>
      </material>
    </visual>
  </link>

  <!-- Joint 1: Revolute -->
  <joint name="joint1" type="revolute">
    <parent link="base_link"/>
    <child link="link1"/>
    <origin xyz="0 0 0.05" rpy="0 0 0"/>
    <axis xyz="0 0 1"/>
    <limit effort="10" velocity="1.0" lower="-1.57" upper="1.57"/>
  </joint>

  <!-- Joint 2: Revolute -->
  <joint name="joint2" type="revolute">
    <parent link="link1"/>
    <child link="link2"/>
    <origin xyz="0 0 0.4" rpy="0 0 0"/>
    <axis xyz="0 0 1"/>
    <limit effort="10" velocity="1.0" lower="-1.57" upper="1.57"/>
  </joint>

</robot>
